Workbook

Sheet Start Here
A1: Start Here
A2: Starting roster for 2026-27: every campus of the five Area Offices (266, from the 26-27 SY Area Office Unit Assignments). The 11 campuses with a PTA on the Texas PTA roster are marked as having a PTO/PTA; every other campus shows "Nothing received yet" until it sends something.
A4: What this is
A5: One Google Sheet, one Google Form and one dashboard page. The person on the ParentOrgDocs inbox fills in the form for each email that arrives: the campus, whether it has a PTO or PTA, and the documents attached. A script files each document in that campus's Drive folder, marks the item Received in the Campus Register tab and adds a row to the Submission Log tab. The dashboard page reads the tabs every time it is opened, so it is always current. Officers come in a second way: you paste the Excel export of the HISD Parent Organization Officer Update Form into the Officer Form Paste tab and choose PTO/PTA Tracker > Import officers. The script lists each officer on the Officers tab under the campus the form names and marks Officer Information Accepted (it needs no review). On the dashboard, click a campus to see its checklist, what is pending, its recent activity and, for signed-in C1s and FACE staff, its officers. Everyone uses the same dashboard address. Leadership just opens it. C1 Coordinators and FACE staff choose Sign in on the page and type a passcode, which lets them open the files and mark each document Accepted or Needs correction.
A6: Definitions
A7: Registered: these three are accepted for the school year: training certificate, the organization's bylaws and the officer information form. A PTA counts the same way: it sends the training certificate and the officer information form, and its bylaws box is filled from the Texas PTA spreadsheet.
A8: Legalized: these are all accepted: training certificate, the organization's bylaws, the officer information form, annual budget report or meeting minutes showing budget approval, proof of 501(c) status and bank account verification letter from financial institution listing two authorized account signers. The dashboard calls this Can Fundraise. For a PTA, the bylaws, budget (SOA 990), 501(c) status (PTA status) and bank account (JoinPTA.org activation) boxes come from the Texas PTA spreadsheet each week. A reviewer can mark any document Not Needed for a PTO/PTA; it then counts as done.
A9: Item status: Not Received, Received (waiting for review), Accepted, Needs Correction, or Not Needed. Accepted and Not Needed count. An uploaded document is set to Received, and a reviewer checks it off on the dashboard (or in the Campus Register tab). The officer information form is set to Accepted as soon as it comes in: nobody reviews it.
A10: Has PTO or PTA: Yes, No, or Not Yet Confirmed (the default; the dashboard shows it as "Nothing received yet"). A campus becomes Yes by itself when it sends documents or an officer form, when a reviewer checks a document off, or when the Texas PTA roster lists it. A form answer of Not Yet Confirmed never overwrites a Yes or a No.
A11: Set it up once
A12: 1. Save this file to Google Drive, open it with Google Sheets and choose File > Save as Google Sheets. Keep it in the Google account that should own the documents (see Accounts, below).
A13: 2. Choose Extensions > Apps Script. Replace everything in Code.gs with the contents of the Code.gs file. Click + next to Files, choose HTML, name it Dashboard (exactly) and paste in the contents of Dashboard.html. Click Save.
... A86: 1. Only Articles of Incorporation is one-time and carries forward; everything else, including the bank and EIN letter and insurance, renews yearly. 2. The school year starts July 1 (Settings). 3. Campuses are the ones marked Yes (122) or Unsure (32) in the TB PTO/PTA Tracker; the campuses marked No are not included. Area Office comes from the 26-27 SY Area Office Unit Assignments workbook. 23 names are spelled differently in the two files (see Roster Match Notes) and 2 campuses have no Area Office yet. 4. The officer information form is the HISD Parent Organization Officer Update Form (Microsoft Forms). Its Excel export is pasted into Officer Form Paste and imported; one form covers one organization and names its school, so no guessing is needed. The importer ignores a leading asterisk when matching campus names (the register has *Kinder HSPVA). It has not been checked whether that form's school list uses exactly the register's spellings. A school that is not in the register, even after ignoring capitals, punctuation and High School / Middle School / Elementary wording, is added as a new campus, so check the Campus Register for a near-duplicate after an import; a campus name typed by hand that is not in the register is flagged, never added. 5. C1 review: C1s and FACE staff sign in on the dashboard with a passcode (kept only as a salted hash) instead of a Google sign-in, because Google tells a script who is looking only when they are in the sheet owner's organization. The log records the signed-in person's name. Who is a C1 for which campus comes only from the C1 Assignments tab; who is staff comes only from the Dashboard sign-ins tab. 6. Decided: FACE's What to Submit guide lists five documents plus the officer form for annual registration, but Registered counts only training, bylaws and officer information. The budget proof, 501(c) proof, bank and EIN letter and Articles count toward Legalized only. Insurance is optional and counts toward neither. 7. Booster clubs are not tracked: the officer import leaves their forms out entirely. 8. Changed on October 2, 2026: the Tax ID (EIN) letter and the bank letter are one item (Bank and EIN Letter), liability and property insurance is optional, and every document, bank letters included, is filed in the campus folder (there is no separate bank folder). 9. Changed on October 9, 2026: Registered and Legalized use FACE's wording, and Legalized means six documents (Articles of Incorporation is no longer needed). Reviewers check each document off on the dashboard (there, needs correction, not there, or not needed) with remarks that go into the email to the PTO/PTA. Every campus of every Area Office is listed; a campus counts as having a PTO/PTA once it sends something or is on the Texas PTA roster. 10. Changed on October 15, 2026: the officer information form counts as soon as it comes in; a PTA is tracked on the training certificate and the officer information form; Articles of Incorporation and Insurance are no longer asked for; files keep the name they were sent with; the dashboard has a My campus page and a Waiting on column.

Sheet Summary
A1: PTO/PTA Registration Summary
A2: Starting roster: every campus of the five Area Offices (266). 11 PTAs from the Texas PTA roster. No documents received yet.
A3: School year | C3: =Settings!$C$5 | D3: Change it on the Settings sheet.
A5: Milestones
A6: Measure | C6: Campuses | D6: % of confirmed PTO/PTA
A7: Campuses being tracked | C7: =COUNTIFS('Campus Register'!$A$2:$A$600,$C$3)
A8: Have a PTO/PTA (confirmed Yes) | C8: =COUNTIFS('Campus Register'!$A$2:$A$600,$C$3,'Campus Register'!$D$2:$D$600,"Yes")
A9: Confirmed no PTO/PTA | C9: =COUNTIFS('Campus Register'!$A$2:$A$600,$C$3,'Campus Register'!$D$2:$D$600,"No")
A10: Not yet confirmed | C10: =C7-C8-C9
A11: Started (at least one document received) | C11: =COUNTIFS('Campus Register'!$A$2:$A$600,$C$3,'Campus Register'!$D$2:$D$600,"Yes",'Campus Register'!$O$2:$O$600,">0") | D11: =IF($C$8=0,"",C11/$C$8)
A12: Registered (includes Legalized) | C12: =COUNTIFS('Campus Register'!$A$2:$A$600,$C$3,'Campus Register'!$D$2:$D$600,"Yes",'Campus Register'!$P$2:$P$600,">="&Settings!$C$12) | D12: =IF($C$8=0,"",C12/$C$8)
A13: Legalized | C13: =COUNTIFS('Campus Register'!$A$2:$A$600,$C$3,'Campus Register'!$D$2:$D$600,"Yes",'Campus Register'!$Q$2:$Q$600,">="&Settings!$C$13) | D13: =IF($C$8=0,"",C13/$C$8)
A16: Status of each campus (each counted once)
A17: Status | C17: Campuses
A18: Legalized | C18: =COUNTIFS('Campus Register'!$A$2:$A$600,$C$3,'Campus Register'!$R$2:$R$600,A18)
A19: Registered | C19: =COUNTIFS('Campus Register'!$A$2:$A$600,$C$3,'Campus Register'!$R$2:$R$600,A19)
A20: In Progress | C20: =COUNTIFS('Campus Register'!$A$2:$A$600,$C$3,'Campus Register'!$R$2:$R$600,A20)
A21: Not Started | C21: =COUNTIFS('Campus Register'!$A$2:$A$600,$C$3,'Campus Register'!$R$2:$R$600,A21)
A22: No PTO/PTA | C22: =COUNTIFS('Campus Register'!$A$2:$A$600,$C$3,'Campus Register'!$R$2:$R$600,A22)
A23: Not Yet Confirmed | C23: =COUNTIFS('Campus Register'!$A$2:$A$600,$C$3,'Campus Register'!$R$2:$R$600,A23)
A24: Total (should equal campuses being tracked) | C24: =SUM(C18:C23) | D24: =IF(C24=C7,"OK","Check: does not match roster")
A27: Documents (campuses with a PTO/PTA)
A28: Document | C28: Accepted | D28: Received, awaiting review | E28: Needs correction | F28: Not received | G28: % accepted
A29: Bylaws | C29: =COUNTIFS('Campus Register'!$A$2:$A$600,$C$3,'Campus Register'!$D$2:$D$600,"Yes",'Campus Register'!$G$2:$G$600,"Accepted") | D29: =COUNTIFS('Campus Register'!$A$2:$A$600,$C$3,'Campus Register'!$D$2:$D$600,"Yes",'Campus Register'!$G$2:$G$600,"Received") | E29: =COUNTIFS('Campus Register'!$A$2:$A$600,$C$3,'Campus Register'!$D$2:$D$600,"Yes",'Campus Register'!$G$2:$G$600,"Needs Correction") | F29: =COUNTIFS('Campus Register'!$A$2:$A$600,$C$3,'Campus Register'!$D$2:$D$600,"Yes",'Campus Register'!$G$2:$G$600,"Not Received") | G29: =IF($C$8=0,"",C29/$C$8)
A30: Officer Information | C30: =COUNTIFS('Campus Register'!$A$2:$A$600,$C$3,'Campus Register'!$D$2:$D$600,"Yes",'Campus Register'!$H$2:$H$600,"Accepted") | D30: =COUNTIFS('Campus Register'!$A$2:$A$600,$C$3,'Campus Register'!$D$2:$D$600,"Yes",'Campus Register'!$H$2:$H$600,"Received") | E30: =COUNTIFS('Campus Register'!$A$2:$A$600,$C$3,'Campus Register'!$D$2:$D$600,"Yes",'Campus Register'!$H$2:$H$600,"Needs Correction") | F30: =COUNTIFS('Campus Register'!$A$2:$A$600,$C$3,'Campus Register'!$D$2:$D$600,"Yes",'Campus Register'!$H$2:$H$600,"Not Received") | G30: =IF($C$8=0,"",C30/$C$8)
A31: Training Certificate | C31: =COUNTIFS('Campus Register'!$A$2:$A$600,$C$3,'Campus Register'!$D$2:$D$600,"Yes",'Campus Register'!$I$2:$I$600,"Accepted") | D31: =COUNTIFS('Campus Register'!$A$2:$A$600,$C$3,'Campus Register'!$D$2:$D$600,"Yes",'Campus Register'!$I$2:$I$600,"Received") | E31: =COUNTIFS('Campus Register'!$A$2:$A$600,$C$3,'Campus Register'!$D$2:$D$600,"Yes",'Campus Register'!$I$2:$I$600,"Needs Correction") | F31: =COUNTIFS('Campus Register'!$A$2:$A$600,$C$3,'Campus Register'!$D$2:$D$600,"Yes",'Campus Register'!$I$2:$I$600,"Not Received") | G31: =IF($C$8=0,"",C31/$C$8)
A32: Budget or Financial Report | C32: =COUNTIFS('Campus Register'!$A$2:$A$600,$C$3,'Campus Register'!$D$2:$D$600,"Yes",'Campus Register'!$J$2:$J$600,"Accepted") | D32: =COUNTIFS('Campus Register'!$A$2:$A$600,$C$3,'Campus Register'!$D$2:$D$600,"Yes",'Campus Register'!$J$2:$J$600,"Received") | E32: =COUNTIFS('Campus Register'!$A$2:$A$600,$C$3,'Campus Register'!$D$2:$D$600,"Yes",'Campus Register'!$J$2:$J$600,"Needs Correction") | F32: =COUNTIFS('Campus Register'!$A$2:$A$600,$C$3,'Campus Register'!$D$2:$D$600,"Yes",'Campus Register'!$J$2:$J$600,"Not Received") | G32: =IF($C$8=0,"",C32/$C$8)
A33: Proof of 501c Status | C33: =COUNTIFS('Campus Register'!$A$2:$A$600,$C$3,'Campus Register'!$D$2:$D$600,"Yes",'Campus Register'!$K$2:$K$600,"Accepted") | D33: =COUNTIFS('Campus Register'!$A$2:$A$600,$C$3,'Campus Register'!$D$2:$D$600,"Yes",'Campus Register'!$K$2:$K$600,"Received") | E33: =COUNTIFS('Campus Register'!$A$2:$A$600,$C$3,'Campus Register'!$D$2:$D$600,"Yes",'Campus Register'!$K$2:$K$600,"Needs Correction") | F33: =COUNTIFS('Campus Register'!$A$2:$A$600,$C$3,'Campus Register'!$D$2:$D$600,"Yes",'Campus Register'!$K$2:$K$600,"Not Received") | G33: =IF($C$8=0,"",C33/$C$8)
A34: Bank Verification Letter | C34: =COUNTIFS('Campus Register'!$A$2:$A$600,$C$3,'Campus Register'!$D$2:$D$600,"Yes",'Campus Register'!$L$2:$L$600,"Accepted") | D34: =COUNTIFS('Campus Register'!$A$2:$A$600,$C$3,'Campus Register'!$D$2:$D$600,"Yes",'Campus Register'!$L$2:$L$600,"Received") | E34: =COUNTIFS('Campus Register'!$A$2:$A$600,$C$3,'Campus Register'!$D$2:$D$600,"Yes",'Campus Register'!$L$2:$L$600,"Needs Correction") | F34: =COUNTIFS('Campus Register'!$A$2:$A$600,$C$3,'Campus Register'!$D$2:$D$600,"Yes",'Campus Register'!$L$2:$L$600,"Not Received") | G34: =IF($C$8=0,"",C34/$C$8)
A35: Articles of Incorporation | C35: =COUNTIFS('Campus Register'!$A$2:$A$600,$C$3,'Campus Register'!$D$2:$D$600,"Yes",'Campus Register'!$M$2:$M$600,"Accepted") | D35: =COUNTIFS('Campus Register'!$A$2:$A$600,$C$3,'Campus Register'!$D$2:$D$600,"Yes",'Campus Register'!$M$2:$M$600,"Received") | E35: =COUNTIFS('Campus Register'!$A$2:$A$600,$C$3,'Campus Register'!$D$2:$D$600,"Yes",'Campus Register'!$M$2:$M$600,"Needs Correction") | F35: =COUNTIFS('Campus Register'!$A$2:$A$600,$C$3,'Campus Register'!$D$2:$D$600,"Yes",'Campus Register'!$M$2:$M$600,"Not Received") | G35: =IF($C$8=0,"",C35/$C$8)
A36: Insurance (optional) | C36: =COUNTIFS('Campus Register'!$A$2:$A$600,$C$3,'Campus Register'!$D$2:$D$600,"Yes",'Campus Register'!$N$2:$N$600,"Accepted") | D36: =COUNTIFS('Campus Register'!$A$2:$A$600,$C$3,'Campus Register'!$D$2:$D$600,"Yes",'Campus Register'!$N$2:$N$600,"Received") | E36: =COUNTIFS('Campus Register'!$A$2:$A$600,$C$3,'Campus Register'!$D$2:$D$600,"Yes",'Campus Register'!$N$2:$N$600,"Needs Correction") | F36: =COUNTIFS('Campus Register'!$A$2:$A$600,$C$3,'Campus Register'!$D$2:$D$600,"Yes",'Campus Register'!$N$2:$N$600,"Not Received") | G36: =IF($C$8=0,"",C36/$C$8)
A39: Area Offices
A40: Area Office | C40: Campuses | D40: Have a PTO/PTA | E40: Registered | F40: Legalized | G40: % legalized
A41: =Settings!E18 | C41: =COUNTIFS('Campus Register'!$A$2:$A$600,$C$3,'Campus Register'!$C$2:$C$600,$A41) | D41: =COUNTIFS('Campus Register'!$A$2:$A$600,$C$3,'Campus Register'!$C$2:$C$600,$A41,'Campus Register'!$D$2:$D$600,"Yes") | E41: =COUNTIFS('Campus Register'!$A$2:$A$600,$C$3,'Campus Register'!$C$2:$C$600,$A41,'Campus Register'!$D$2:$D$600,"Yes",'Campus Register'!$P$2:$P$600,">="&Settings!$C$12) | F41: =COUNTIFS('Campus Register'!$A$2:$A$600,$C$3,'Campus Register'!$C$2:$C$600,$A41,'Campus Register'!$D$2:$D$600,"Yes",'Campus Register'!$Q$2:$Q$600,">="&Settings!$C$13) | G41: =IF(D41=0,"",F41/D41)
A42: =Settings!E19 | C42: =COUNTIFS('Campus Register'!$A$2:$A$600,$C$3,'Campus Register'!$C$2:$C$600,$A42) | D42: =COUNTIFS('Campus Register'!$A$2:$A$600,$C$3,'Campus Register'!$C$2:$C$600,$A42,'Campus Register'!$D$2:$D$600,"Yes") | E42: =COUNTIFS('Campus Register'!$A$2:$A$600,$C$3,'Campus Register'!$C$2:$C$600,$A42,'Campus Register'!$D$2:$D$600,"Yes",'Campus Register'!$P$2:$P$600,">="&Settings!$C$12) | F42: =COUNTIFS('Campus Register'!$A$2:$A$600,$C$3,'Campus Register'!$C$2:$C$600,$A42,'Campus Register'!$D$2:$D$600,"Yes",'Campus Register'!$Q$2:$Q$600,">="&Settings!$C$13) | G42: =IF(D42=0,"",F42/D42)
A43: =Settings!E20 | C43: =COUNTIFS('Campus Register'!$A$2:$A$600,$C$3,'Campus Register'!$C$2:$C$600,$A43) | D43: =COUNTIFS('Campus Register'!$A$2:$A$600,$C$3,'Campus Register'!$C$2:$C$600,$A43,'Campus Register'!$D$2:$D$600,"Yes") | E43: =COUNTIFS('Campus Register'!$A$2:$A$600,$C$3,'Campus Register'!$C$2:$C$600,$A43,'Campus Register'!$D$2:$D$600,"Yes",'Campus Register'!$P$2:$P$600,">="&Settings!$C$12) | F43: =COUNTIFS('Campus Register'!$A$2:$A$600,$C$3,'Campus Register'!$C$2:$C$600,$A43,'Campus Register'!$D$2:$D$600,"Yes",'Campus Register'!$Q$2:$Q$600,">="&Settings!$C$13) | G43: =IF(D43=0,"",F43/D43)
A44: =Settings!E21 | C44: =COUNTIFS('Campus Register'!$A$2:$A$600,$C$3,'Campus Register'!$C$2:$C$600,$A44) | D44: =COUNTIFS('Campus Register'!$A$2:$A$600,$C$3,'Campus Register'!$C$2:$C$600,$A44,'Campus Register'!$D$2:$D$600,"Yes") | E44: =COUNTIFS('Campus Register'!$A$2:$A$600,$C$3,'Campus Register'!$C$2:$C$600,$A44,'Campus Register'!$D$2:$D$600,"Yes",'Campus Register'!$P$2:$P$600,">="&Settings!$C$12) | F44: =COUNTIFS('Campus Register'!$A$2:$A$600,$C$3,'Campus Register'!$C$2:$C$600,$A44,'Campus Register'!$D$2:$D$600,"Yes",'Campus Register'!$Q$2:$Q$600,">="&Settings!$C$13) | G44: =IF(D44=0,"",F44/D44)
A45: =Settings!E22 | C45: =COUNTIFS('Campus Register'!$A$2:$A$600,$C$3,'Campus Register'!$C$2:$C$600,$A45) | D45: =COUNTIFS('Campus Register'!$A$2:$A$600,$C$3,'Campus Register'!$C$2:$C$600,$A45,'Campus Register'!$D$2:$D$600,"Yes") | E45: =COUNTIFS('Campus Register'!$A$2:$A$600,$C$3,'Campus Register'!$C$2:$C$600,$A45,'Campus Register'!$D$2:$D$600,"Yes",'Campus Register'!$P$2:$P$600,">="&Settings!$C$12) | F45: =COUNTIFS('Campus Register'!$A$2:$A$600,$C$3,'Campus Register'!$C$2:$C$600,$A45,'Campus Register'!$D$2:$D$600,"Yes",'Campus Register'!$Q$2:$Q$600,">="&Settings!$C$13) | G45: =IF(D45=0,"",F45/D45)
A48: Data checks
A49: Campuses with documents on file but Has PTO or PTA not confirmed as Yes | C49: =COUNTIFS('Campus Register'!$A$2:$A$600,$C$3,'Campus Register'!$D$2:$D$600,"<>Yes",'Campus Register'!$O$2:$O$600,">0") | D49: Ask the coordinator to confirm these campuses.
...

Sheet Campus Register
A1: School Year | B1: Campus | C1: Area Office | D1: Has PTO or PTA | E1: Org Type | F1: Org Name | G1: Bylaws | H1: Officer Information | I1: Training Certificate | J1: Budget or Financial Report | K1: Proof of 501c Status | L1: Bank Verification Letter | M1: Articles of Incorporation | N1: Insurance | O1: Items Received | P1: Registration Items Accepted | Q1: Legalization Items Accepted | R1: Status | S1: Items Awaiting Review | T1: Items Needing Correction | U1: Not Yet Accepted
A2: 2026-27 | B2: Anderson ES | C2: NES Elementary | D2: Not Yet Confirmed | G2: Not Received | H2: Not Received | I2: Not Received | J2: Not Received | K2: Not Received | L2: Not Received | M2: Not Received | N2: Not Received | O2: =IF($B2="","",COUNTIF(G2:N2,"Accepted")+COUNTIF(G2:N2,"Received")+COUNTIF(G2:N2,"Needs Correction")) | P2: =IF($B2="","",SUMPRODUCT(((G2:N2="Accepted")+(G2:N2="Not Needed"))*(Settings!$C$11:$J$11="Yes"))) | Q2: =IF($B2="","",SUMPRODUCT(((G2:N2="Accepted")+(G2:N2="Not Needed"))*(Settings!$C$15:$J$15="Yes"))) | R2: =IF($B2="","",IF($D2="No","No PTO/PTA",IF($D2<>"Yes","Not Yet Confirmed",IF($Q2>=Settings!$C$13,"Legalized",IF($P2>=Settings!$C$12,"Registered",IF($O2>0,"In Progress","Not Started")))))) | S2: =IF($B2="","",COUNTIF(G2:N2,"Received")) | T2: =IF($B2="","",COUNTIF(G2:N2,"Needs Correction")) | U2: =IF($B2="","",IF($D2<>"Yes","",IF($Q2>=Settings!$C$13,"None",MID(IF(AND(G2<>"Accepted",G2<>"Not Needed",Settings!$C$15="Yes"),", "&G$1,"")&IF(AND(H2<>"Accepted",H2<>"Not Needed",Settings!$D$15="Yes"),", "&H$1,"")&IF(AND(I2<>"Accepted",I2<>"Not Needed",Settings!$E$15="Yes"),", "&I$1,"")&IF(AND(J2<>"Accepted",J2<>"Not Needed",Settings!$F$15="Yes"),", "&J$1,"")&IF(AND(K2<>"Accepted",K2<>"Not Needed",Settings!$G$15="Yes"),", "&K$1,"")&IF(AND(L2<>"Accepted",L2<>"Not Needed",Settings!$H$15="Yes"),", "&L$1,"")&IF(AND(M2<>"Accepted",M2<>"Not Needed",Settings!$I$15="Yes"),", "&M$1,"")&IF(AND(N2<>"Accepted",N2<>"Not Needed",Settings!$J$15="Yes"),", "&N$1,""),3,400))))
A3: 2026-27 | B3: Ashford ES | C3: NES Elementary | D3: Not Yet Confirmed | G3: Not Received | H3: Not Received | I3: Not Received | J3: Not Received | K3: Not Received | L3: Not Received | M3: Not Received | N3: Not Received | O3: =IF($B3="","",COUNTIF(G3:N3,"Accepted")+COUNTIF(G3:N3,"Received")+COUNTIF(G3:N3,"Needs Correction")) | P3: =IF($B3="","",SUMPRODUCT(((G3:N3="Accepted")+(G3:N3="Not Needed"))*(Settings!$C$11:$J$11="Yes"))) | Q3: =IF($B3="","",SUMPRODUCT(((G3:N3="Accepted")+(G3:N3="Not Needed"))*(Settings!$C$15:$J$15="Yes"))) | R3: =IF($B3="","",IF($D3="No","No PTO/PTA",IF($D3<>"Yes","Not Yet Confirmed",IF($Q3>=Settings!$C$13,"Legalized",IF($P3>=Settings!$C$12,"Registered",IF($O3>0,"In Progress","Not Started")))))) | S3: =IF($B3="","",COUNTIF(G3:N3,"Received")) | T3: =IF($B3="","",COUNTIF(G3:N3,"Needs Correction")) | U3: =IF($B3="","",IF($D3<>"Yes","",IF($Q3>=Settings!$C$13,"None",MID(IF(AND(G3<>"Accepted",G3<>"Not Needed",Settings!$C$15="Yes"),", "&G$1,"")&IF(AND(H3<>"Accepted",H3<>"Not Needed",Settings!$D$15="Yes"),", "&H$1,"")&IF(AND(I3<>"Accepted",I3<>"Not Needed",Settings!$E$15="Yes"),", "&I$1,"")&IF(AND(J3<>"Accepted",J3<>"Not Needed",Settings!$F$15="Yes"),", "&J$1,"")&IF(AND(K3<>"Accepted",K3<>"Not Needed",Settings!$G$15="Yes"),", "&K$1,"")&IF(AND(L3<>"Accepted",L3<>"Not Needed",Settings!$H$15="Yes"),", "&L$1,"")&IF(AND(M3<>"Accepted",M3<>"Not Needed",Settings!$I$15="Yes"),", "&M$1,"")&IF(AND(N3<>"Accepted",N3<>"Not Needed",Settings!$J$15="Yes"),", "&N$1,""),3,400))))
A4: 2026-27 | B4: Askew ES | C4: NES Elementary | D4: Not Yet Confirmed | G4: Not Received | H4: Not Received | I4: Not Received | J4: Not Received | K4: Not Received | L4: Not Received | M4: Not Received | N4: Not Received | O4: =IF($B4="","",COUNTIF(G4:N4,"Accepted")+COUNTIF(G4:N4,"Received")+COUNTIF(G4:N4,"Needs Correction")) | P4: =IF($B4="","",SUMPRODUCT(((G4:N4="Accepted")+(G4:N4="Not Needed"))*(Settings!$C$11:$J$11="Yes"))) | Q4: =IF($B4="","",SUMPRODUCT(((G4:N4="Accepted")+(G4:N4="Not Needed"))*(Settings!$C$15:$J$15="Yes"))) | R4: =IF($B4="","",IF($D4="No","No PTO/PTA",IF($D4<>"Yes","Not Yet Confirmed",IF($Q4>=Settings!$C$13,"Legalized",IF($P4>=Settings!$C$12,"Registered",IF($O4>0,"In Progress","Not Started")))))) | S4: =IF($B4="","",COUNTIF(G4:N4,"Received")) | T4: =IF($B4="","",COUNTIF(G4:N4,"Needs Correction")) | U4: =IF($B4="","",IF($D4<>"Yes","",IF($Q4>=Settings!$C$13,"None",MID(IF(AND(G4<>"Accepted",G4<>"Not Needed",Settings!$C$15="Yes"),", "&G$1,"")&IF(AND(H4<>"Accepted",H4<>"Not Needed",Settings!$D$15="Yes"),", "&H$1,"")&IF(AND(I4<>"Accepted",I4<>"Not Needed",Settings!$E$15="Yes"),", "&I$1,"")&IF(AND(J4<>"Accepted",J4<>"Not Needed",Settings!$F$15="Yes"),", "&J$1,"")&IF(AND(K4<>"Accepted",K4<>"Not Needed",Settings!$G$15="Yes"),", "&K$1,"")&IF(AND(L4<>"Accepted",L4<>"Not Needed",Settings!$H$15="Yes"),", "&L$1,"")&IF(AND(M4<>"Accepted",M4<>"Not Needed",Settings!$I$15="Yes"),", "&M$1,"")&IF(AND(N4<>"Accepted",N4<>"Not Needed",Settings!$J$15="Yes"),", "&N$1,""),3,400))))
A5: 2026-27 | B5: Atherton ES | C5: NES Elementary | D5: Not Yet Confirmed | G5: Not Received | H5: Not Received | I5: Not Received | J5: Not Received | K5: Not Received | L5: Not Received | M5: Not Received | N5: Not Received | O5: =IF($B5="","",COUNTIF(G5:N5,"Accepted")+COUNTIF(G5:N5,"Received")+COUNTIF(G5:N5,"Needs Correction")) | P5: =IF($B5="","",SUMPRODUCT(((G5:N5="Accepted")+(G5:N5="Not Needed"))*(Settings!$C$11:$J$11="Yes"))) | Q5: =IF($B5="","",SUMPRODUCT(((G5:N5="Accepted")+(G5:N5="Not Needed"))*(Settings!$C$15:$J$15="Yes"))) | R5: =IF($B5="","",IF($D5="No","No PTO/PTA",IF($D5<>"Yes","Not Yet Confirmed",IF($Q5>=Settings!$C$13,"Legalized",IF($P5>=Settings!$C$12,"Registered",IF($O5>0,"In Progress","Not Started")))))) | S5: =IF($B5="","",COUNTIF(G5:N5,"Received")) | T5: =IF($B5="","",COUNTIF(G5:N5,"Needs Correction")) | U5: =IF($B5="","",IF($D5<>"Yes","",IF($Q5>=Settings!$C$13,"None",MID(IF(AND(G5<>"Accepted",G5<>"Not Needed",Settings!$C$15="Yes"),", "&G$1,"")&IF(AND(H5<>"Accepted",H5<>"Not Needed",Settings!$D$15="Yes"),", "&H$1,"")&IF(AND(I5<>"Accepted",I5<>"Not Needed",Settings!$E$15="Yes"),", "&I$1,"")&IF(AND(J5<>"Accepted",J5<>"Not Needed",Settings!$F$15="Yes"),", "&J$1,"")&IF(AND(K5<>"Accepted",K5<>"Not Needed",Settings!$G$15="Yes"),", "&K$1,"")&IF(AND(L5<>"Accepted",L5<>"Not Needed",Settings!$H$15="Yes"),", "&L$1,"")&IF(AND(M5<>"Accepted",M5<>"Not Needed",Settings!$I$15="Yes"),", "&M$1,"")&IF(AND(N5<>"Accepted",N5<>"Not Needed",Settings!$J$15="Yes"),", "&N$1,""),3,400))))
A6: 2026-27 | B6: Barrick ES | C6: NES Elementary | D6: Not Yet Confirmed | G6: Not Received | H6: Not Received | I6: Not Received | J6: Not Received | K6: Not Received | L6: Not Received | M6: Not Received | N6: Not Received | O6: =IF($B6="","",COUNTIF(G6:N6,"Accepted")+COUNTIF(G6:N6,"Received")+COUNTIF(G6:N6,"Needs Correction")) | P6: =IF($B6="","",SUMPRODUCT(((G6:N6="Accepted")+(G6:N6="Not Needed"))*(Settings!$C$11:$J$11="Yes"))) | Q6: =IF($B6="","",SUMPRODUCT(((G6:N6="Accepted")+(G6:N6="Not Needed"))*(Settings!$C$15:$J$15="Yes"))) | R6: =IF($B6="","",IF($D6="No","No PTO/PTA",IF($D6<>"Yes","Not Yet Confirmed",IF($Q6>=Settings!$C$13,"Legalized",IF($P6>=Settings!$C$12,"Registered",IF($O6>0,"In Progress","Not Started")))))) | S6: =IF($B6="","",COUNTIF(G6:N6,"Received")) | T6: =IF($B6="","",COUNTIF(G6:N6,"Needs Correction")) | U6: =IF($B6="","",IF($D6<>"Yes","",IF($Q6>=Settings!$C$13,"None",MID(IF(AND(G6<>"Accepted",G6<>"Not Needed",Settings!$C$15="Yes"),", "&G$1,"")&IF(AND(H6<>"Accepted",H6<>"Not Needed",Settings!$D$15="Yes"),", "&H$1,"")&IF(AND(I6<>"Accepted",I6<>"Not Needed",Settings!$E$15="Yes"),", "&I$1,"")&IF(AND(J6<>"Accepted",J6<>"Not Needed",Settings!$F$15="Yes"),", "&J$1,"")&IF(AND(K6<>"Accepted",K6<>"Not Needed",Settings!$G$15="Yes"),", "&K$1,"")&IF(AND(L6<>"Accepted",L6<>"Not Needed",Settings!$H$15="Yes"),", "&L$1,"")&IF(AND(M6<>"Accepted",M6<>"Not Needed",Settings!$I$15="Yes"),", "&M$1,"")&IF(AND(N6<>"Accepted",N6<>"Not Needed",Settings!$J$15="Yes"),", "&N$1,""),3,400))))
A7: 2026-27 | B7: Bastian ES | C7: NES Elementary | D7: No | G7: Not Received | H7: Not Received | I7: Not Received | J7: Not Received | K7: Not Received | L7: Not Received | M7: Not Received | N7: Not Received | O7: =IF($B7="","",COUNTIF(G7:N7,"Accepted")+COUNTIF(G7:N7,"Received")+COUNTIF(G7:N7,"Needs Correction")) | P7: =IF($B7="","",SUMPRODUCT(((G7:N7="Accepted")+(G7:N7="Not Needed"))*(Settings!$C$11:$J$11="Yes"))) | Q7: =IF($B7="","",SUMPRODUCT(((G7:N7="Accepted")+(G7:N7="Not Needed"))*(Settings!$C$15:$J$15="Yes"))) | R7: =IF($B7="","",IF($D7="No","No PTO/PTA",IF($D7<>"Yes","Not Yet Confirmed",IF($Q7>=Settings!$C$13,"Legalized",IF($P7>=Settings!$C$12,"Registered",IF($O7>0,"In Progress","Not Started")))))) | S7: =IF($B7="","",COUNTIF(G7:N7,"Received")) | T7: =IF($B7="","",COUNTIF(G7:N7,"Needs Correction")) | U7: =IF($B7="","",IF($D7<>"Yes","",IF($Q7>=Settings!$C$13,"None",MID(IF(AND(G7<>"Accepted",G7<>"Not Needed",Settings!$C$15="Yes"),", "&G$1,"")&IF(AND(H7<>"Accepted",H7<>"Not Needed",Settings!$D$15="Yes"),", "&H$1,"")&IF(AND(I7<>"Accepted",I7<>"Not Needed",Settings!$E$15="Yes"),", "&I$1,"")&IF(AND(J7<>"Accepted",J7<>"Not Needed",Settings!$F$15="Yes"),", "&J$1,"")&IF(AND(K7<>"Accepted",K7<>"Not Needed",Settings!$G$15="Yes"),", "&K$1,"")&IF(AND(L7<>"Accepted",L7<>"Not Needed",Settings!$H$15="Yes"),", "&L$1,"")&IF(AND(M7<>"Accepted",M7<>"Not Needed",Settings!$I$15="Yes"),", "&M$1,"")&IF(AND(N7<>"Accepted",N7<>"Not Needed",Settings!$J$15="Yes"),", "&N$1,""),3,400))))
A8: 2026-27 | B8: Benbrook ES | C8: NES Elementary | D8: No | G8: Not Received | H8: Not Received | I8: Not Received | J8: Not Received | K8: Not Received | L8: Not Received | M8: Not Received | N8: Not Received | O8: =IF($B8="","",COUNTIF(G8:N8,"Accepted")+COUNTIF(G8:N8,"Received")+COUNTIF(G8:N8,"Needs Correction")) | P8: =IF($B8="","",SUMPRODUCT(((G8:N8="Accepted")+(G8:N8="Not Needed"))*(Settings!$C$11:$J$11="Yes"))) | Q8: =IF($B8="","",SUMPRODUCT(((G8:N8="Accepted")+(G8:N8="Not Needed"))*(Settings!$C$15:$J$15="Yes"))) | R8: =IF($B8="","",IF($D8="No","No PTO/PTA",IF($D8<>"Yes","Not Yet Confirmed",IF($Q8>=Settings!$C$13,"Legalized",IF($P8>=Settings!$C$12,"Registered",IF($O8>0,"In Progress","Not Started")))))) | S8: =IF($B8="","",COUNTIF(G8:N8,"Received")) | T8: =IF($B8="","",COUNTIF(G8:N8,"Needs Correction")) | U8: =IF($B8="","",IF($D8<>"Yes","",IF($Q8>=Settings!$C$13,"None",MID(IF(AND(G8<>"Accepted",G8<>"Not Needed",Settings!$C$15="Yes"),", "&G$1,"")&IF(AND(H8<>"Accepted",H8<>"Not Needed",Settings!$D$15="Yes"),", "&H$1,"")&IF(AND(I8<>"Accepted",I8<>"Not Needed",Settings!$E$15="Yes"),", "&I$1,"")&IF(AND(J8<>"Accepted",J8<>"Not Needed",Settings!$F$15="Yes"),", "&J$1,"")&IF(AND(K8<>"Accepted",K8<>"Not Needed",Settings!$G$15="Yes"),", "&K$1,"")&IF(AND(L8<>"Accepted",L8<>"Not Needed",Settings!$H$15="Yes"),", "&L$1,"")&IF(AND(M8<>"Accepted",M8<>"Not Needed",Settings!$I$15="Yes"),", "&M$1,"")&IF(AND(N8<>"Accepted",N8<>"Not Needed",Settings!$J$15="Yes"),", "&N$1,""),3,400))))
A9: 2026-27 | B9: Berry ES | C9: NES Elementary | D9: Not Yet Confirmed | G9: Not Received | H9: Not Received | I9: Not Received | J9: Not Received | K9: Not Received | L9: Not Received | M9: Not Received | N9: Not Received | O9: =IF($B9="","",COUNTIF(G9:N9,"Accepted")+COUNTIF(G9:N9,"Received")+COUNTIF(G9:N9,"Needs Correction")) | P9: =IF($B9="","",SUMPRODUCT(((G9:N9="Accepted")+(G9:N9="Not Needed"))*(Settings!$C$11:$J$11="Yes"))) | Q9: =IF($B9="","",SUMPRODUCT(((G9:N9="Accepted")+(G9:N9="Not Needed"))*(Settings!$C$15:$J$15="Yes"))) | R9: =IF($B9="","",IF($D9="No","No PTO/PTA",IF($D9<>"Yes","Not Yet Confirmed",IF($Q9>=Settings!$C$13,"Legalized",IF($P9>=Settings!$C$12,"Registered",IF($O9>0,"In Progress","Not Started")))))) | S9: =IF($B9="","",COUNTIF(G9:N9,"Received")) | T9: =IF($B9="","",COUNTIF(G9:N9,"Needs Correction")) | U9: =IF($B9="","",IF($D9<>"Yes","",IF($Q9>=Settings!$C$13,"None",MID(IF(AND(G9<>"Accepted",G9<>"Not Needed",Settings!$C$15="Yes"),", "&G$1,"")&IF(AND(H9<>"Accepted",H9<>"Not Needed",Settings!$D$15="Yes"),", "&H$1,"")&IF(AND(I9<>"Accepted",I9<>"Not Needed",Settings!$E$15="Yes"),", "&I$1,"")&IF(AND(J9<>"Accepted",J9<>"Not Needed",Settings!$F$15="Yes"),", "&J$1,"")&IF(AND(K9<>"Accepted",K9<>"Not Needed",Settings!$G$15="Yes"),", "&K$1,"")&IF(AND(L9<>"Accepted",L9<>"Not Needed",Settings!$H$15="Yes"),", "&L$1,"")&IF(AND(M9<>"Accepted",M9<>"Not Needed",Settings!$I$15="Yes"),", "&M$1,"")&IF(AND(N9<>"Accepted",N9<>"Not Needed",Settings!$J$15="Yes"),", "&N$1,""),3,400))))
A10: 2026-27 | B10: Blackshear ES | C10: NES Elementary | D10: Not Yet Confirmed | G10: Not Received | H10: Not Received | I10: Not Received | J10: Not Received | K10: Not Received | L10: Not Received | M10: Not Received | N10: Not Received | O10: =IF($B10="","",COUNTIF(G10:N10,"Accepted")+COUNTIF(G10:N10,"Received")+COUNTIF(G10:N10,"Needs Correction")) | P10: =IF($B10="","",SUMPRODUCT(((G10:N10="Accepted")+(G10:N10="Not Needed"))*(Settings!$C$11:$J$11="Yes"))) | Q10: =IF($B10="","",SUMPRODUCT(((G10:N10="Accepted")+(G10:N10="Not Needed"))*(Settings!$C$15:$J$15="Yes"))) | R10: =IF($B10="","",IF($D10="No","No PTO/PTA",IF($D10<>"Yes","Not Yet Confirmed",IF($Q10>=Settings!$C$13,"Legalized",IF($P10>=Settings!$C$12,"Registered",IF($O10>0,"In Progress","Not Started")))))) | S10: =IF($B10="","",COUNTIF(G10:N10,"Received")) | T10: =IF($B10="","",COUNTIF(G10:N10,"Needs Correction")) | U10: =IF($B10="","",IF($D10<>"Yes","",IF($Q10>=Settings!$C$13,"None",MID(IF(AND(G10<>"Accepted",G10<>"Not Needed",Settings!$C$15="Yes"),", "&G$1,"")&IF(AND(H10<>"Accepted",H10<>"Not Needed",Settings!$D$15="Yes"),", "&H$1,"")&IF(AND(I10<>"Accepted",I10<>"Not Needed",Settings!$E$15="Yes"),", "&I$1,"")&IF(AND(J10<>"Accepted",J10<>"Not Needed",Settings!$F$15="Yes"),", "&J$1,"")&IF(AND(K10<>"Accepted",K10<>"Not Needed",Settings!$G$15="Yes"),", "&K$1,"")&IF(AND(L10<>"Accepted",L10<>"Not Needed",Settings!$H$15="Yes"),", "&L$1,"")&IF(AND(M10<>"Accepted",M10<>"Not Needed",Settings!$I$15="Yes"),", "&M$1,"")&IF(AND(N10<>"Accepted",N10<>"Not Needed",Settings!$J$15="Yes"),", "&N$1,""),3,400))))
A11: 2026-27 | B11: Bonham ES | C11: NES Elementary | D11: Not Yet Confirmed | G11: Not Received | H11: Not Received | I11: Not Received | J11: Not Received | K11: Not Received | L11: Not Received | M11: Not Received | N11: Not Received | O11: =IF($B11="","",COUNTIF(G11:N11,"Accepted")+COUNTIF(G11:N11,"Received")+COUNTIF(G11:N11,"Needs Correction")) | P11: =IF($B11="","",SUMPRODUCT(((G11:N11="Accepted")+(G11:N11="Not Needed"))*(Settings!$C$11:$J$11="Yes"))) | Q11: =IF($B11="","",SUMPRODUCT(((G11:N11="Accepted")+(G11:N11="Not Needed"))*(Settings!$C$15:$J$15="Yes"))) | R11: =IF($B11="","",IF($D11="No","No PTO/PTA",IF($D11<>"Yes","Not Yet Confirmed",IF($Q11>=Settings!$C$13,"Legalized",IF($P11>=Settings!$C$12,"Registered",IF($O11>0,"In Progress","Not Started")))))) | S11: =IF($B11="","",COUNTIF(G11:N11,"Received")) | T11: =IF($B11="","",COUNTIF(G11:N11,"Needs Correction")) | U11: =IF($B11="","",IF($D11<>"Yes","",IF($Q11>=Settings!$C$13,"None",MID(IF(AND(G11<>"Accepted",G11<>"Not Needed",Settings!$C$15="Yes"),", "&G$1,"")&IF(AND(H11<>"Accepted",H11<>"Not Needed",Settings!$D$15="Yes"),", "&H$1,"")&IF(AND(I11<>"Accepted",I11<>"Not Needed",Settings!$E$15="Yes"),", "&I$1,"")&IF(AND(J11<>"Accepted",J11<>"Not Needed",Settings!$F$15="Yes"),", "&J$1,"")&IF(AND(K11<>"Accepted",K11<>"Not Needed",Settings!$G$15="Yes"),", "&K$1,"")&IF(AND(L11<>"Accepted",L11<>"Not Needed",Settings!$H$15="Yes"),", "&L$1,"")&IF(AND(M11<>"Accepted",M11<>"Not Needed",Settings!$I$15="Yes"),", "&M$1,"")&IF(AND(N11<>"Accepted",N11<>"Not Needed",Settings!$J$15="Yes"),", "&N$1,""),3,400))))
A12: 2026-27 | B12: Bonner ES | C12: NES Elementary | D12: Not Yet Confirmed | G12: Not Received | H12: Not Received | I12: Not Received | J12: Not Received | K12: Not Received | L12: Not Received | M12: Not Received | N12: Not Received | O12: =IF($B12="","",COUNTIF(G12:N12,"Accepted")+COUNTIF(G12:N12,"Received")+COUNTIF(G12:N12,"Needs Correction")) | P12: =IF($B12="","",SUMPRODUCT(((G12:N12="Accepted")+(G12:N12="Not Needed"))*(Settings!$C$11:$J$11="Yes"))) | Q12: =IF($B12="","",SUMPRODUCT(((G12:N12="Accepted")+(G12:N12="Not Needed"))*(Settings!$C$15:$J$15="Yes"))) | R12: =IF($B12="","",IF($D12="No","No PTO/PTA",IF($D12<>"Yes","Not Yet Confirmed",IF($Q12>=Settings!$C$13,"Legalized",IF($P12>=Settings!$C$12,"Registered",IF($O12>0,"In Progress","Not Started")))))) | S12: =IF($B12="","",COUNTIF(G12:N12,"Received")) | T12: =IF($B12="","",COUNTIF(G12:N12,"Needs Correction")) | U12: =IF($B12="","",IF($D12<>"Yes","",IF($Q12>=Settings!$C$13,"None",MID(IF(AND(G12<>"Accepted",G12<>"Not Needed",Settings!$C$15="Yes"),", "&G$1,"")&IF(AND(H12<>"Accepted",H12<>"Not Needed",Settings!$D$15="Yes"),", "&H$1,"")&IF(AND(I12<>"Accepted",I12<>"Not Needed",Settings!$E$15="Yes"),", "&I$1,"")&IF(AND(J12<>"Accepted",J12<>"Not Needed",Settings!$F$15="Yes"),", "&J$1,"")&IF(AND(K12<>"Accepted",K12<>"Not Needed",Settings!$G$15="Yes"),", "&K$1,"")&IF(AND(L12<>"Accepted",L12<>"Not Needed",Settings!$H$15="Yes"),", "&L$1,"")&IF(AND(M12<>"Accepted",M12<>"Not Needed",Settings!$I$15="Yes"),", "&M$1,"")&IF(AND(N12<>"Accepted",N12<>"Not Needed",Settings!$J$15="Yes"),", "&N$1,""),3,400))))
A13: 2026-27 | B13: Browning ES | C13: NES Elementary | D13: Yes | E13: PTA | G13: Accepted | H13: Not Received | I13: Not Received | J13: Not Received | K13: Accepted | L13: Accepted | M13: Not Received | N13: Not Received | O13: =IF($B13="","",COUNTIF(G13:N13,"Accepted")+COUNTIF(G13:N13,"Received")+COUNTIF(G13:N13,"Needs Correction")) | P13: =IF($B13="","",SUMPRODUCT(((G13:N13="Accepted")+(G13:N13="Not Needed"))*(Settings!$C$11:$J$11="Yes"))) | Q13: =IF($B13="","",SUMPRODUCT(((G13:N13="Accepted")+(G13:N13="Not Needed"))*(Settings!$C$15:$J$15="Yes"))) | R13: =IF($B13="","",IF($D13="No","No PTO/PTA",IF($D13<>"Yes","Not Yet Confirmed",IF($Q13>=Settings!$C$13,"Legalized",IF($P13>=Settings!$C$12,"Registered",IF($O13>0,"In Progress","Not Started")))))) | S13: =IF($B13="","",COUNTIF(G13:N13,"Received")) | T13: =IF($B13="","",COUNTIF(G13:N13,"Needs Correction")) | U13: =IF($B13="","",IF($D13<>"Yes","",IF($Q13>=Settings!$C$13,"None",MID(IF(AND(G13<>"Accepted",G13<>"Not Needed",Settings!$C$15="Yes"),", "&G$1,"")&IF(AND(H13<>"Accepted",H13<>"Not Needed",Settings!$D$15="Yes"),", "&H$1,"")&IF(AND(I13<>"Accepted",I13<>"Not Needed",Settings!$E$15="Yes"),", "&I$1,"")&IF(AND(J13<>"Accepted",J13<>"Not Needed",Settings!$F$15="Yes"),", "&J$1,"")&IF(AND(K13<>"Accepted",K13<>"Not Needed",Settings!$G$15="Yes"),", "&K$1,"")&IF(AND(L13<>"Accepted",L13<>"Not Needed",Settings!$H$15="Yes"),", "&L$1,"")&IF(AND(M13<>"Accepted",M13<>"Not Needed",Settings!$I$15="Yes"),", "&M$1,"")&IF(AND(N13<>"Accepted",N13<>"Not Needed",Settings!$J$15="Yes"),", "&N$1,""),3,400))))
A14: 2026-27 | B14: Bruce ES | C14: NES Elementary | D14: No | G14: Not Received | H14: Not Received | I14: Not Received | J14: Not Received | K14: Not Received | L14: Not Received | M14: Not Received | N14: Not Received | O14: =IF($B14="","",COUNTIF(G14:N14,"Accepted")+COUNTIF(G14:N14,"Received")+COUNTIF(G14:N14,"Needs Correction")) | P14: =IF($B14="","",SUMPRODUCT(((G14:N14="Accepted")+(G14:N14="Not Needed"))*(Settings!$C$11:$J$11="Yes"))) | Q14: =IF($B14="","",SUMPRODUCT(((G14:N14="Accepted")+(G14:N14="Not Needed"))*(Settings!$C$15:$J$15="Yes"))) | R14: =IF($B14="","",IF($D14="No","No PTO/PTA",IF($D14<>"Yes","Not Yet Confirmed",IF($Q14>=Settings!$C$13,"Legalized",IF($P14>=Settings!$C$12,"Registered",IF($O14>0,"In Progress","Not Started")))))) | S14: =IF($B14="","",COUNTIF(G14:N14,"Received")) | T14: =IF($B14="","",COUNTIF(G14:N14,"Needs Correction")) | U14: =IF($B14="","",IF($D14<>"Yes","",IF($Q14>=Settings!$C$13,"None",MID(IF(AND(G14<>"Accepted",G14<>"Not Needed",Settings!$C$15="Yes"),", "&G$1,"")&IF(AND(H14<>"Accepted",H14<>"Not Needed",Settings!$D$15="Yes"),", "&H$1,"")&IF(AND(I14<>"Accepted",I14<>"Not Needed",Settings!$E$15="Yes"),", "&I$1,"")&IF(AND(J14<>"Accepted",J14<>"Not Needed",Settings!$F$15="Yes"),", "&J$1,"")&IF(AND(K14<>"Accepted",K14<>"Not Needed",Settings!$G$15="Yes"),", "&K$1,"")&IF(AND(L14<>"Accepted",L14<>"Not Needed",Settings!$H$15="Yes"),", "&L$1,"")&IF(AND(M14<>"Accepted",M14<>"Not Needed",Settings!$I$15="Yes"),", "&M$1,"")&IF(AND(N14<>"Accepted",N14<>"Not Needed",Settings!$J$15="Yes"),", "&N$1,""),3,400))))
A15: 2026-27 | B15: Carrillo ES | C15: NES Elementary | D15: Not Yet Confirmed | G15: Not Received | H15: Not Received | I15: Not Received | J15: Not Received | K15: Not Received | L15: Not Received | M15: Not Received | N15: Not Received | O15: =IF($B15="","",COUNTIF(G15:N15,"Accepted")+COUNTIF(G15:N15,"Received")+COUNTIF(G15:N15,"Needs Correction")) | P15: =IF($B15="","",SUMPRODUCT(((G15:N15="Accepted")+(G15:N15="Not Needed"))*(Settings!$C$11:$J$11="Yes"))) | Q15: =IF($B15="","",SUMPRODUCT(((G15:N15="Accepted")+(G15:N15="Not Needed"))*(Settings!$C$15:$J$15="Yes"))) | R15: =IF($B15="","",IF($D15="No","No PTO/PTA",IF($D15<>"Yes","Not Yet Confirmed",IF($Q15>=Settings!$C$13,"Legalized",IF($P15>=Settings!$C$12,"Registered",IF($O15>0,"In Progress","Not Started")))))) | S15: =IF($B15="","",COUNTIF(G15:N15,"Received")) | T15: =IF($B15="","",COUNTIF(G15:N15,"Needs Correction")) | U15: =IF($B15="","",IF($D15<>"Yes","",IF($Q15>=Settings!$C$13,"None",MID(IF(AND(G15<>"Accepted",G15<>"Not Needed",Settings!$C$15="Yes"),", "&G$1,"")&IF(AND(H15<>"Accepted",H15<>"Not Needed",Settings!$D$15="Yes"),", "&H$1,"")&IF(AND(I15<>"Accepted",I15<>"Not Needed",Settings!$E$15="Yes"),", "&I$1,"")&IF(AND(J15<>"Accepted",J15<>"Not Needed",Settings!$F$15="Yes"),", "&J$1,"")&IF(AND(K15<>"Accepted",K15<>"Not Needed",Settings!$G$15="Yes"),", "&K$1,"")&IF(AND(L15<>"Accepted",L15<>"Not Needed",Settings!$H$15="Yes"),", "&L$1,"")&IF(AND(M15<>"Accepted",M15<>"Not Needed",Settings!$I$15="Yes"),", "&M$1,"")&IF(AND(N15<>"Accepted",N15<>"Not Needed",Settings!$J$15="Yes"),", "&N$1,""),3,400))))
A16: 2026-27 | B16: Coop ES | C16: NES Elementary | D16: Not Yet Confirmed | G16: Not Received | H16: Not Received | I16: Not Received | J16: Not Received | K16: Not Received | L16: Not Received | M16: Not Received | N16: Not Received | O16: =IF($B16="","",COUNTIF(G16:N16,"Accepted")+COUNTIF(G16:N16,"Received")+COUNTIF(G16:N16,"Needs Correction")) | P16: =IF($B16="","",SUMPRODUCT(((G16:N16="Accepted")+(G16:N16="Not Needed"))*(Settings!$C$11:$J$11="Yes"))) | Q16: =IF($B16="","",SUMPRODUCT(((G16:N16="Accepted")+(G16:N16="Not Needed"))*(Settings!$C$15:$J$15="Yes"))) | R16: =IF($B16="","",IF($D16="No","No PTO/PTA",IF($D16<>"Yes","Not Yet Confirmed",IF($Q16>=Settings!$C$13,"Legalized",IF($P16>=Settings!$C$12,"Registered",IF($O16>0,"In Progress","Not Started")))))) | S16: =IF($B16="","",COUNTIF(G16:N16,"Received")) | T16: =IF($B16="","",COUNTIF(G16:N16,"Needs Correction")) | U16: =IF($B16="","",IF($D16<>"Yes","",IF($Q16>=Settings!$C$13,"None",MID(IF(AND(G16<>"Accepted",G16<>"Not Needed",Settings!$C$15="Yes"),", "&G$1,"")&IF(AND(H16<>"Accepted",H16<>"Not Needed",Settings!$D$15="Yes"),", "&H$1,"")&IF(AND(I16<>"Accepted",I16<>"Not Needed",Settings!$E$15="Yes"),", "&I$1,"")&IF(AND(J16<>"Accepted",J16<>"Not Needed",Settings!$F$15="Yes"),", "&J$1,"")&IF(AND(K16<>"Accepted",K16<>"Not Needed",Settings!$G$15="Yes"),", "&K$1,"")&IF(AND(L16<>"Accepted",L16<>"Not Needed",Settings!$H$15="Yes"),", "&L$1,"")&IF(AND(M16<>"Accepted",M16<>"Not Needed",Settings!$I$15="Yes"),", "&M$1,"")&IF(AND(N16<>"Accepted",N16<>"Not Needed",Settings!$J$15="Yes"),", "&N$1,""),3,400))))
A17: 2026-27 | B17: Crockett ES | C17: NES Elementary | D17: Not Yet Confirmed | G17: Not Received | H17: Not Received | I17: Not Received | J17: Not Received | K17: Not Received | L17: Not Received | M17: Not Received | N17: Not Received | O17: =IF($B17="","",COUNTIF(G17:N17,"Accepted")+COUNTIF(G17:N17,"Received")+COUNTIF(G17:N17,"Needs Correction")) | P17: =IF($B17="","",SUMPRODUCT(((G17:N17="Accepted")+(G17:N17="Not Needed"))*(Settings!$C$11:$J$11="Yes"))) | Q17: =IF($B17="","",SUMPRODUCT(((G17:N17="Accepted")+(G17:N17="Not Needed"))*(Settings!$C$15:$J$15="Yes"))) | R17: =IF($B17="","",IF($D17="No","No PTO/PTA",IF($D17<>"Yes","Not Yet Confirmed",IF($Q17>=Settings!$C$13,"Legalized",IF($P17>=Settings!$C$12,"Registered",IF($O17>0,"In Progress","Not Started")))))) | S17: =IF($B17="","",COUNTIF(G17:N17,"Received")) | T17: =IF($B17="","",COUNTIF(G17:N17,"Needs Correction")) | U17: =IF($B17="","",IF($D17<>"Yes","",IF($Q17>=Settings!$C$13,"None",MID(IF(AND(G17<>"Accepted",G17<>"Not Needed",Settings!$C$15="Yes"),", "&G$1,"")&IF(AND(H17<>"Accepted",H17<>"Not Needed",Settings!$D$15="Yes"),", "&H$1,"")&IF(AND(I17<>"Accepted",I17<>"Not Needed",Settings!$E$15="Yes"),", "&I$1,"")&IF(AND(J17<>"Accepted",J17<>"Not Needed",Settings!$F$15="Yes"),", "&J$1,"")&IF(AND(K17<>"Accepted",K17<>"Not Needed",Settings!$G$15="Yes"),", "&K$1,"")&IF(AND(L17<>"Accepted",L17<>"Not Needed",Settings!$H$15="Yes"),", "&L$1,"")&IF(AND(M17<>"Accepted",M17<>"Not Needed",Settings!$I$15="Yes"),", "&M$1,"")&IF(AND(N17<>"Accepted",N17<>"Not Needed",Settings!$J$15="Yes"),", "&N$1,""),3,400))))
A18: 2026-27 | B18: DeZavala ES | C18: NES Elementary | D18: Not Yet Confirmed | G18: Not Received | H18: Not Received | I18: Not Received | J18: Not Received | K18: Not Received | L18: Not Received | M18: Not Received | N18: Not Received | O18: =IF($B18="","",COUNTIF(G18:N18,"Accepted")+COUNTIF(G18:N18,"Received")+COUNTIF(G18:N18,"Needs Correction")) | P18: =IF($B18="","",SUMPRODUCT(((G18:N18="Accepted")+(G18:N18="Not Needed"))*(Settings!$C$11:$J$11="Yes"))) | Q18: =IF($B18="","",SUMPRODUCT(((G18:N18="Accepted")+(G18:N18="Not Needed"))*(Settings!$C$15:$J$15="Yes"))) | R18: =IF($B18="","",IF($D18="No","No PTO/PTA",IF($D18<>"Yes","Not Yet Confirmed",IF($Q18>=Settings!$C$13,"Legalized",IF($P18>=Settings!$C$12,"Registered",IF($O18>0,"In Progress","Not Started")))))) | S18: =IF($B18="","",COUNTIF(G18:N18,"Received")) | T18: =IF($B18="","",COUNTIF(G18:N18,"Needs Correction")) | U18: =IF($B18="","",IF($D18<>"Yes","",IF($Q18>=Settings!$C$13,"None",MID(IF(AND(G18<>"Accepted",G18<>"Not Needed",Settings!$C$15="Yes"),", "&G$1,"")&IF(AND(H18<>"Accepted",H18<>"Not Needed",Settings!$D$15="Yes"),", "&H$1,"")&IF(AND(I18<>"Accepted",I18<>"Not Needed",Settings!$E$15="Yes"),", "&I$1,"")&IF(AND(J18<>"Accepted",J18<>"Not Needed",Settings!$F$15="Yes"),", "&J$1,"")&IF(AND(K18<>"Accepted",K18<>"Not Needed",Settings!$G$15="Yes"),", "&K$1,"")&IF(AND(L18<>"Accepted",L18<>"Not Needed",Settings!$H$15="Yes"),", "&L$1,"")&IF(AND(M18<>"Accepted",M18<>"Not Needed",Settings!$I$15="Yes"),", "&M$1,"")&IF(AND(N18<>"Accepted",N18<>"Not Needed",Settings!$J$15="Yes"),", "&N$1,""),3,400))))
A19: 2026-27 | B19: Eliot ES | C19: NES Elementary | D19: Not Yet Confirmed | G19: Not Received | H19: Not Received | I19: Not Received | J19: Not Received | K19: Not Received | L19: Not Received | M19: Not Received | N19: Not Received | O19: =IF($B19="","",COUNTIF(G19:N19,"Accepted")+COUNTIF(G19:N19,"Received")+COUNTIF(G19:N19,"Needs Correction")) | P19: =IF($B19="","",SUMPRODUCT(((G19:N19="Accepted")+(G19:N19="Not Needed"))*(Settings!$C$11:$J$11="Yes"))) | Q19: =IF($B19="","",SUMPRODUCT(((G19:N19="Accepted")+(G19:N19="Not Needed"))*(Settings!$C$15:$J$15="Yes"))) | R19: =IF($B19="","",IF($D19="No","No PTO/PTA",IF($D19<>"Yes","Not Yet Confirmed",IF($Q19>=Settings!$C$13,"Legalized",IF($P19>=Settings!$C$12,"Registered",IF($O19>0,"In Progress","Not Started")))))) | S19: =IF($B19="","",COUNTIF(G19:N19,"Received")) | T19: =IF($B19="","",COUNTIF(G19:N19,"Needs Correction")) | U19: =IF($B19="","",IF($D19<>"Yes","",IF($Q19>=Settings!$C$13,"None",MID(IF(AND(G19<>"Accepted",G19<>"Not Needed",Settings!$C$15="Yes"),", "&G$1,"")&IF(AND(H19<>"Accepted",H19<>"Not Needed",Settings!$D$15="Yes"),", "&H$1,"")&IF(AND(I19<>"Accepted",I19<>"Not Needed",Settings!$E$15="Yes"),", "&I$1,"")&IF(AND(J19<>"Accepted",J19<>"Not Needed",Settings!$F$15="Yes"),", "&J$1,"")&IF(AND(K19<>"Accepted",K19<>"Not Needed",Settings!$G$15="Yes"),", "&K$1,"")&IF(AND(L19<>"Accepted",L19<>"Not Needed",Settings!$H$15="Yes"),", "&L$1,"")&IF(AND(M19<>"Accepted",M19<>"Not Needed",Settings!$I$15="Yes"),", "&M$1,"")&IF(AND(N19<>"Accepted",N19<>"Not Needed",Settings!$J$15="Yes"),", "&N$1,""),3,400))))
A20: 2026-27 | B20: Elmore ES | C20: NES Elementary | D20: Not Yet Confirmed | G20: Not Received | H20: Not Received | I20: Not Received | J20: Not Received | K20: Not Received | L20: Not Received | M20: Not Received | N20: Not Received | O20: =IF($B20="","",COUNTIF(G20:N20,"Accepted")+COUNTIF(G20:N20,"Received")+COUNTIF(G20:N20,"Needs Correction")) | P20: =IF($B20="","",SUMPRODUCT(((G20:N20="Accepted")+(G20:N20="Not Needed"))*(Settings!$C$11:$J$11="Yes"))) | Q20: =IF($B20="","",SUMPRODUCT(((G20:N20="Accepted")+(G20:N20="Not Needed"))*(Settings!$C$15:$J$15="Yes"))) | R20: =IF($B20="","",IF($D20="No","No PTO/PTA",IF($D20<>"Yes","Not Yet Confirmed",IF($Q20>=Settings!$C$13,"Legalized",IF($P20>=Settings!$C$12,"Registered",IF($O20>0,"In Progress","Not Started")))))) | S20: =IF($B20="","",COUNTIF(G20:N20,"Received")) | T20: =IF($B20="","",COUNTIF(G20:N20,"Needs Correction")) | U20: =IF($B20="","",IF($D20<>"Yes","",IF($Q20>=Settings!$C$13,"None",MID(IF(AND(G20<>"Accepted",G20<>"Not Needed",Settings!$C$15="Yes"),", "&G$1,"")&IF(AND(H20<>"Accepted",H20<>"Not Needed",Settings!$D$15="Yes"),", "&H$1,"")&IF(AND(I20<>"Accepted",I20<>"Not Needed",Settings!$E$15="Yes"),", "&I$1,"")&IF(AND(J20<>"Accepted",J20<>"Not Needed",Settings!$F$15="Yes"),", "&J$1,"")&IF(AND(K20<>"Accepted",K20<>"Not Needed",Settings!$G$15="Yes"),", "&K$1,"")&IF(AND(L20<>"Accepted",L20<>"Not Needed",Settings!$H$15="Yes"),", "&L$1,"")&IF(AND(M20<>"Accepted",M20<>"Not Needed",Settings!$I$15="Yes"),", "&M$1,"")&IF(AND(N20<>"Accepted",N20<>"Not Needed",Settings!$J$15="Yes"),", "&N$1,""),3,400))))
A21: 2026-27 | B21: Gallegos ES | C21: NES Elementary | D21: Not Yet Confirmed | G21: Not Received | H21: Not Received | I21: Not Received | J21: Not Received | K21: Not Received | L21: Not Received | M21: Not Received | N21: Not Received | O21: =IF($B21="","",COUNTIF(G21:N21,"Accepted")+COUNTIF(G21:N21,"Received")+COUNTIF(G21:N21,"Needs Correction")) | P21: =IF($B21="","",SUMPRODUCT(((G21:N21="Accepted")+(G21:N21="Not Needed"))*(Settings!$C$11:$J$11="Yes"))) | Q21: =IF($B21="","",SUMPRODUCT(((G21:N21="Accepted")+(G21:N21="Not Needed"))*(Settings!$C$15:$J$15="Yes"))) | R21: =IF($B21="","",IF($D21="No","No PTO/PTA",IF($D21<>"Yes","Not Yet Confirmed",IF($Q21>=Settings!$C$13,"Legalized",IF($P21>=Settings!$C$12,"Registered",IF($O21>0,"In Progress","Not Started")))))) | S21: =IF($B21="","",COUNTIF(G21:N21,"Received")) | T21: =IF($B21="","",COUNTIF(G21:N21,"Needs Correction")) | U21: =IF($B21="","",IF($D21<>"Yes","",IF($Q21>=Settings!$C$13,"None",MID(IF(AND(G21<>"Accepted",G21<>"Not Needed",Settings!$C$15="Yes"),", "&G$1,"")&IF(AND(H21<>"Accepted",H21<>"Not Needed",Settings!$D$15="Yes"),", "&H$1,"")&IF(AND(I21<>"Accepted",I21<>"Not Needed",Settings!$E$15="Yes"),", "&I$1,"")&IF(AND(J21<>"Accepted",J21<>"Not Needed",Settings!$F$15="Yes"),", "&J$1,"")&IF(AND(K21<>"Accepted",K21<>"Not Needed",Settings!$G$15="Yes"),", "&K$1,"")&IF(AND(L21<>"Accepted",L21<>"Not Needed",Settings!$H$15="Yes"),", "&L$1,"")&IF(AND(M21<>"Accepted",M21<>"Not Needed",Settings!$I$15="Yes"),", "&M$1,"")&IF(AND(N21<>"Accepted",N21<>"Not Needed",Settings!$J$15="Yes"),", "&N$1,""),3,400))))
A22: 2026-27 | B22: Golfcrest ES | C22: NES Elementary | D22: Not Yet Confirmed | G22: Not Received | H22: Not Received | I22: Not Received | J22: Not Received | K22: Not Received | L22: Not Received | M22: Not Received | N22: Not Received | O22: =IF($B22="","",COUNTIF(G22:N22,"Accepted")+COUNTIF(G22:N22,"Received")+COUNTIF(G22:N22,"Needs Correction")) | P22: =IF($B22="","",SUMPRODUCT(((G22:N22="Accepted")+(G22:N22="Not Needed"))*(Settings!$C$11:$J$11="Yes"))) | Q22: =IF($B22="","",SUMPRODUCT(((G22:N22="Accepted")+(G22:N22="Not Needed"))*(Settings!$C$15:$J$15="Yes"))) | R22: =IF($B22="","",IF($D22="No","No PTO/PTA",IF($D22<>"Yes","Not Yet Confirmed",IF($Q22>=Settings!$C$13,"Legalized",IF($P22>=Settings!$C$12,"Registered",IF($O22>0,"In Progress","Not Started")))))) | S22: =IF($B22="","",COUNTIF(G22:N22,"Received")) | T22: =IF($B22="","",COUNTIF(G22:N22,"Needs Correction")) | U22: =IF($B22="","",IF($D22<>"Yes","",IF($Q22>=Settings!$C$13,"None",MID(IF(AND(G22<>"Accepted",G22<>"Not Needed",Settings!$C$15="Yes"),", "&G$1,"")&IF(AND(H22<>"Accepted",H22<>"Not Needed",Settings!$D$15="Yes"),", "&H$1,"")&IF(AND(I22<>"Accepted",I22<>"Not Needed",Settings!$E$15="Yes"),", "&I$1,"")&IF(AND(J22<>"Accepted",J22<>"Not Needed",Settings!$F$15="Yes"),", "&J$1,"")&IF(AND(K22<>"Accepted",K22<>"Not Needed",Settings!$G$15="Yes"),", "&K$1,"")&IF(AND(L22<>"Accepted",L22<>"Not Needed",Settings!$H$15="Yes"),", "&L$1,"")&IF(AND(M22<>"Accepted",M22<>"Not Needed",Settings!$I$15="Yes"),", "&M$1,"")&IF(AND(N22<>"Accepted",N22<>"Not Needed",Settings!$J$15="Yes"),", "&N$1,""),3,400))))
A23: 2026-27 | B23: Gross ES | C23: NES Elementary | D23: No | G23: Not Received | H23: Not Received | I23: Not Received | J23: Not Received | K23: Not Received | L23: Not Received | M23: Not Received | N23: Not Received | O23: =IF($B23="","",COUNTIF(G23:N23,"Accepted")+COUNTIF(G23:N23,"Received")+COUNTIF(G23:N23,"Needs Correction")) | P23: =IF($B23="","",SUMPRODUCT(((G23:N23="Accepted")+(G23:N23="Not Needed"))*(Settings!$C$11:$J$11="Yes"))) | Q23: =IF($B23="","",SUMPRODUCT(((G23:N23="Accepted")+(G23:N23="Not Needed"))*(Settings!$C$15:$J$15="Yes"))) | R23: =IF($B23="","",IF($D23="No","No PTO/PTA",IF($D23<>"Yes","Not Yet Confirmed",IF($Q23>=Settings!$C$13,"Legalized",IF($P23>=Settings!$C$12,"Registered",IF($O23>0,"In Progress","Not Started")))))) | S23: =IF($B23="","",COUNTIF(G23:N23,"Received")) | T23: =IF($B23="","",COUNTIF(G23:N23,"Needs Correction")) | U23: =IF($B23="","",IF($D23<>"Yes","",IF($Q23>=Settings!$C$13,"None",MID(IF(AND(G23<>"Accepted",G23<>"Not Needed",Settings!$C$15="Yes"),", "&G$1,"")&IF(AND(H23<>"Accepted",H23<>"Not Needed",Settings!$D$15="Yes"),", "&H$1,"")&IF(AND(I23<>"Accepted",I23<>"Not Needed",Settings!$E$15="Yes"),", "&I$1,"")&IF(AND(J23<>"Accepted",J23<>"Not Needed",Settings!$F$15="Yes"),", "&J$1,"")&IF(AND(K23<>"Accepted",K23<>"Not Needed",Settings!$G$15="Yes"),", "&K$1,"")&IF(AND(L23<>"Accepted",L23<>"Not Needed",Settings!$H$15="Yes"),", "&L$1,"")&IF(AND(M23<>"Accepted",M23<>"Not Needed",Settings!$I$15="Yes"),", "&M$1,"")&IF(AND(N23<>"Accepted",N23<>"Not Needed",Settings!$J$15="Yes"),", "&N$1,""),3,400))))
A24: 2026-27 | B24: Harris RP ES | C24: NES Elementary | D24: Not Yet Confirmed | G24: Not Received | H24: Not Received | I24: Not Received | J24: Not Received | K24: Not Received | L24: Not Received | M24: Not Received | N24: Not Received | O24: =IF($B24="","",COUNTIF(G24:N24,"Accepted")+COUNTIF(G24:N24,"Received")+COUNTIF(G24:N24,"Needs Correction")) | P24: =IF($B24="","",SUMPRODUCT(((G24:N24="Accepted")+(G24:N24="Not Needed"))*(Settings!$C$11:$J$11="Yes"))) | Q24: =IF($B24="","",SUMPRODUCT(((G24:N24="Accepted")+(G24:N24="Not Needed"))*(Settings!$C$15:$J$15="Yes"))) | R24: =IF($B24="","",IF($D24="No","No PTO/PTA",IF($D24<>"Yes","Not Yet Confirmed",IF($Q24>=Settings!$C$13,"Legalized",IF($P24>=Settings!$C$12,"Registered",IF($O24>0,"In Progress","Not Started")))))) | S24: =IF($B24="","",COUNTIF(G24:N24,"Received")) | T24: =IF($B24="","",COUNTIF(G24:N24,"Needs Correction")) | U24: =IF($B24="","",IF($D24<>"Yes","",IF($Q24>=Settings!$C$13,"None",MID(IF(AND(G24<>"Accepted",G24<>"Not Needed",Settings!$C$15="Yes"),", "&G$1,"")&IF(AND(H24<>"Accepted",H24<>"Not Needed",Settings!$D$15="Yes"),", "&H$1,"")&IF(AND(I24<>"Accepted",I24<>"Not Needed",Settings!$E$15="Yes"),", "&I$1,"")&IF(AND(J24<>"Accepted",J24<>"Not Needed",Settings!$F$15="Yes"),", "&J$1,"")&IF(AND(K24<>"Accepted",K24<>"Not Needed",Settings!$G$15="Yes"),", "&K$1,"")&IF(AND(L24<>"Accepted",L24<>"Not Needed",Settings!$H$15="Yes"),", "&L$1,"")&IF(AND(M24<>"Accepted",M24<>"Not Needed",Settings!$I$15="Yes"),", "&M$1,"")&IF(AND(N24<>"Accepted",N24<>"Not Needed",Settings!$J$15="Yes"),", "&N$1,""),3,400))))
A25: 2026-27 | B25: Hartsfield ES | C25: NES Elementary | D25: Not Yet Confirmed | G25: Not Received | H25: Not Received | I25: Not Received | J25: Not Received | K25: Not Received | L25: Not Received | M25: Not Received | N25: Not Received | O25: =IF($B25="","",COUNTIF(G25:N25,"Accepted")+COUNTIF(G25:N25,"Received")+COUNTIF(G25:N25,"Needs Correction")) | P25: =IF($B25="","",SUMPRODUCT(((G25:N25="Accepted")+(G25:N25="Not Needed"))*(Settings!$C$11:$J$11="Yes"))) | Q25: =IF($B25="","",SUMPRODUCT(((G25:N25="Accepted")+(G25:N25="Not Needed"))*(Settings!$C$15:$J$15="Yes"))) | R25: =IF($B25="","",IF($D25="No","No PTO/PTA",IF($D25<>"Yes","Not Yet Confirmed",IF($Q25>=Settings!$C$13,"Legalized",IF($P25>=Settings!$C$12,"Registered",IF($O25>0,"In Progress","Not Started")))))) | S25: =IF($B25="","",COUNTIF(G25:N25,"Received")) | T25: =IF($B25="","",COUNTIF(G25:N25,"Needs Correction")) | U25: =IF($B25="","",IF($D25<>"Yes","",IF($Q25>=Settings!$C$13,"None",MID(IF(AND(G25<>"Accepted",G25<>"Not Needed",Settings!$C$15="Yes"),", "&G$1,"")&IF(AND(H25<>"Accepted",H25<>"Not Needed",Settings!$D$15="Yes"),", "&H$1,"")&IF(AND(I25<>"Accepted",I25<>"Not Needed",Settings!$E$15="Yes"),", "&I$1,"")&IF(AND(J25<>"Accepted",J25<>"Not Needed",Settings!$F$15="Yes"),", "&J$1,"")&IF(AND(K25<>"Accepted",K25<>"Not Needed",Settings!$G$15="Yes"),", "&K$1,"")&IF(AND(L25<>"Accepted",L25<>"Not Needed",Settings!$H$15="Yes"),", "&L$1,"")&IF(AND(M25<>"Accepted",M25<>"Not Needed",Settings!$I$15="Yes"),", "&M$1,"")&IF(AND(N25<>"Accepted",N25<>"Not Needed",Settings!$J$15="Yes"),", "&N$1,""),3,400))))
... A28: 2026-27 | B28: Kennedy ES | C28: NES Elementary | D28: No | G28: Not Received | H28: Not Received | I28: Not Received | J28: Not Received | K28: Not Received | L28: Not Received | M28: Not Received | N28: Not Received | O28: =IF($B28="","",COUNTIF(G28:N28,"Accepted")+COUNTIF(G28:N28,"Received")+COUNTIF(G28:N28,"Needs Correction")) | P28: =IF($B28="","",SUMPRODUCT(((G28:N28="Accepted")+(G28:N28="Not Needed"))*(Settings!$C$11:$J$11="Yes"))) | Q28: =IF($B28="","",SUMPRODUCT(((G28:N28="Accepted")+(G28:N28="Not Needed"))*(Settings!$C$15:$J$15="Yes"))) | R28: =IF($B28="","",IF($D28="No","No PTO/PTA",IF($D28<>"Yes","Not Yet Confirmed",IF($Q28>=Settings!$C$13,"Legalized",IF($P28>=Settings!$C$12,"Registered",IF($O28>0,"In Progress","Not Started")))))) | S28: =IF($B28="","",COUNTIF(G28:N28,"Received")) | T28: =IF($B28="","",COUNTIF(G28:N28,"Needs Correction")) | U28: =IF($B28="","",IF($D28<>"Yes","",IF($Q28>=Settings!$C$13,"None",MID(IF(AND(G28<>"Accepted",G28<>"Not Needed",Settings!$C$15="Yes"),", "&G$1,"")&IF(AND(H28<>"Accepted",H28<>"Not Needed",Settings!$D$15="Yes"),", "&H$1,"")&IF(AND(I28<>"Accepted",I28<>"Not Needed",Settings!$E$15="Yes"),", "&I$1,"")&IF(AND(J28<>"Accepted",J28<>"Not Needed",Settings!$F$15="Yes"),", "&J$1,"")&IF(AND(K28<>"Accepted",K28<>"Not Needed",Settings!$G$15="Yes"),", "&K$1,"")&IF(AND(L28<>"Accepted",L28<>"Not Needed",Settings!$H$15="Yes"),", "&L$1,"")&IF(AND(M28<>"Accepted",M28<>"Not Needed",Settings!$I$15="Yes"),", "&M$1,"")&IF(AND(N28<>"Accepted",N28<>"Not Needed",Settings!$J$15="Yes"),", "&N$1,""),3,400))))
A29: 2026-27 | B29: Ketelsen ES | C29: NES Elementary | D29: Yes | E29: PTA | G29: Not Received | H29: Not Received | I29: Not Received | J29: Accepted | K29: Accepted | L29: Accepted | M29: Not Received | N29: Not Received | O29: =IF($B29="","",COUNTIF(G29:N29,"Accepted")+COUNTIF(G29:N29,"Received")+COUNTIF(G29:N29,"Needs Correction")) | P29: =IF($B29="","",SUMPRODUCT(((G29:N29="Accepted")+(G29:N29="Not Needed"))*(Settings!$C$11:$J$11="Yes"))) | Q29: =IF($B29="","",SUMPRODUCT(((G29:N29="Accepted")+(G29:N29="Not Needed"))*(Settings!$C$15:$J$15="Yes"))) | R29: =IF($B29="","",IF($D29="No","No PTO/PTA",IF($D29<>"Yes","Not Yet Confirmed",IF($Q29>=Settings!$C$13,"Legalized",IF($P29>=Settings!$C$12,"Registered",IF($O29>0,"In Progress","Not Started")))))) | S29: =IF($B29="","",COUNTIF(G29:N29,"Received")) | T29: =IF($B29="","",COUNTIF(G29:N29,"Needs Correction")) | U29: =IF($B29="","",IF($D29<>"Yes","",IF($Q29>=Settings!$C$13,"None",MID(IF(AND(G29<>"Accepted",G29<>"Not Needed",Settings!$C$15="Yes"),", "&G$1,"")&IF(AND(H29<>"Accepted",H29<>"Not Needed",Settings!$D$15="Yes"),", "&H$1,"")&IF(AND(I29<>"Accepted",I29<>"Not Needed",Settings!$E$15="Yes"),", "&I$1,"")&IF(AND(J29<>"Accepted",J29<>"Not Needed",Settings!$F$15="Yes"),", "&J$1,"")&IF(AND(K29<>"Accepted",K29<>"Not Needed",Settings!$G$15="Yes"),", "&K$1,"")&IF(AND(L29<>"Accepted",L29<>"Not Needed",Settings!$H$15="Yes"),", "&L$1,"")&IF(AND(M29<>"Accepted",M29<>"Not Needed",Settings!$I$15="Yes"),", "&M$1,"")&IF(AND(N29<>"Accepted",N29<>"Not Needed",Settings!$J$15="Yes"),", "&N$1,""),3,400))))
A30: 2026-27 | B30: Lockhart ES | C30: NES Elementary | D30: Not Yet Confirmed | G30: Not Received | H30: Not Received | I30: Not Received | J30: Not Received | K30: Not Received | L30: Not Received | M30: Not Received | N30: Not Received | O30: =IF($B30="","",COUNTIF(G30:N30,"Accepted")+COUNTIF(G30:N30,"Received")+COUNTIF(G30:N30,"Needs Correction")) | P30: =IF($B30="","",SUMPRODUCT(((G30:N30="Accepted")+(G30:N30="Not Needed"))*(Settings!$C$11:$J$11="Yes"))) | Q30: =IF($B30="","",SUMPRODUCT(((G30:N30="Accepted")+(G30:N30="Not Needed"))*(Settings!$C$15:$J$15="Yes"))) | R30: =IF($B30="","",IF($D30="No","No PTO/PTA",IF($D30<>"Yes","Not Yet Confirmed",IF($Q30>=Settings!$C$13,"Legalized",IF($P30>=Settings!$C$12,"Registered",IF($O30>0,"In Progress","Not Started")))))) | S30: =IF($B30="","",COUNTIF(G30:N30,"Received")) | T30: =IF($B30="","",COUNTIF(G30:N30,"Needs Correction")) | U30: =IF($B30="","",IF($D30<>"Yes","",IF($Q30>=Settings!$C$13,"None",MID(IF(AND(G30<>"Accepted",G30<>"Not Needed",Settings!$C$15="Yes"),", "&G$1,"")&IF(AND(H30<>"Accepted",H30<>"Not Needed",Settings!$D$15="Yes"),", "&H$1,"")&IF(AND(I30<>"Accepted",I30<>"Not Needed",Settings!$E$15="Yes"),", "&I$1,"")&IF(AND(J30<>"Accepted",J30<>"Not Needed",Settings!$F$15="Yes"),", "&J$1,"")&IF(AND(K30<>"Accepted",K30<>"Not Needed",Settings!$G$15="Yes"),", "&K$1,"")&IF(AND(L30<>"Accepted",L30<>"Not Needed",Settings!$H$15="Yes"),", "&L$1,"")&IF(AND(M30<>"Accepted",M30<>"Not Needed",Settings!$I$15="Yes"),", "&M$1,"")&IF(AND(N30<>"Accepted",N30<>"Not Needed",Settings!$J$15="Yes"),", "&N$1,""),3,400))))
